Workbook

Sheet trial
B1: Diamond Star Arabia Industrial Company(Namma)
B2: Trial Balance 01-01-2026 To 31-05-2026
B5: Code | C5: Account | D5: Opening Balance | E5: Debits | F5: Credits | G5: Net Change | H5: Closing Balance | I5: Sub Group
B6: FCA | C6: CONTROL A/Cs
B7: JEC-001 | C7: Journal Entries Control A/C | D7: 0 | E7: 22179370 | F7: 22179370 | G7: =E7-F7 -> 0 | H7: =D7+G7 -> 0
B8: 10 | C8: Cash & Cash Equivallants | G8: =E8-F8 -> 0 | H8: =D8+G8 -> 0
B9: 100 | C9: Petty Cash | G9: =E9-F9 -> 0 | H9: =D9+G9 -> 0
B10: 0100-01 | C10: Petty Cash-Accounts | D10: 0 | E10: 2036922.5 | F10: 2015179.5 | G10: =E10-F10 -> 21743.04 | H10: =D10+G10 -> 21743.04 | I10: Bank balances and cash
B11: 0100-02 | C11: Petty Cash-Expenses | D11: 0 | E11: 123287.42 | F11: 123287.42 | G11: =E11-F11 -> 0 | H11: =D11+G11 -> 0 | I11: Bank balances and cash
B12: 0100-03 | C12: Petty Cash - Material | D12: 0 | E12: 1891895.6 | F12: 1891895.6 | G12: =E12-F12 -> 0 | H12: =D12+G12 -> 0 | I12: Bank balances and cash
B13: 0100-08 | C13: Cash In Hand-2024 | D13: 0 | E13: 405334 | F13: 405334 | G13: =E13-F13 -> 0 | H13: =D13+G13 -> 0 | I13: Bank balances and cash
B14: 102 | C14: Bank | G14: =E14-F14 -> 0 | H14: =D14+G14 -> 0 | I14: Bank balances and cash
B15: 0102-03 | C15: Riyad Bank IBAN- SA3120000001364256539940 | D15: 0 | E15: 6842.5 | F15: 6842.5 | G15: =E15-F15 -> 0 | H15: =D15+G15 -> 0 | I15: Bank balances and cash
B16: 0102-09 | C16: Riyad Bank-136425689994 (DSA) | D16: 0 | E16: 8919704.8 | F16: 8887800.3 | G16: =E16-F16 -> 31904.55 | H16: =D16+G16 -> 31904.55 | I16: Bank balances and cash
B17: 0102-10 | C17: AL RAJHI BANK-45300-001-0006080453175 | D17: 0 | E17: 100 | F17: 0 | G17: =E17-F17 -> 100 | H17: =D17+G17 -> 100 | I17: Bank balances and cash
B18: 101 | C18: Cash In Collection | G18: =E18-F18 -> 0 | H18: =D18+G18 -> 0 | I18: Bank balances and cash
B19: 0101-01 | C19: Cash In Collection | D19: 0 | E19: 2279166.5 | F19: 2279166.5 | G19: =E19-F19 -> 0 | H19: =D19+G19 -> 0 | I19: Bank balances and cash
B20: 400 | C20: Accounts Receivables | G20: =E20-F20 -> 0 | H20: =D20+G20 -> 0
B21: 0400-140 | C21: SAM Advance Co For Industry | D21: 0 | E21: 16145002 | F21: 16146224 | G21: =E21-F21 -> -1222.2 | H21: =D21+G21 -> -1222.2 | I21: Accounts receivable
B22: 0400-138 | C22: United Gulf Factory For Plastics | D22: 0 | E22: 52969 | F22: 52969 | G22: =E22-F22 -> 0 | H22: =D22+G22 -> 0 | I22: Accounts receivable
B23: 0400-137 | C23: Hamed Ateeq Raziq Al-Harbi Environmental Services Est. | D23: 0 | E23: 15719.81 | F23: 15719.85 | G23: =E23-F23 -> -0.04 | H23: =D23+G23 -> -0.04 | I23: Accounts receivable
B24: 0400-02 | C24: AL JAZEERA MODEL PLASTIC FACTORY | D24: 0 | E24: 200701.8 | F24: 167048.05 | G24: =E24-F24 -> 33653.75 | H24: =D24+G24 -> 33653.75 | I24: Accounts receivable
B25: 0605-03 | C25: Saudi Steel Reinforcements Ltd. | D25: 0 | E25: 10399.23 | F25: 10125.4 | G25: =E25-F25 -> 273.83 | H25: =D25+G25 -> 273.83 | I25: Accounts receivable
B26: 0400-10 | C26: MUHAMMAD NASIR SANOSI BAGHDADI PLASTIC FACTORY | D26: 0 | E26: 28230.2 | F26: 25424.3 | G26: =E26-F26 -> 2805.9 | H26: =D26+G26 -> 2805.9 | I26: Accounts receivable
B27: 0400-13 | C27: Rafeeq Bilal Plastic Pvt Ltd | D27: 0 | E27: 67742.45 | F27: 61111 | G27: =E27-F27 -> 6631.45 | H27: =D27+G27 -> 6631.45 | I27: Accounts receivable
B28: 0400-15 | C28: SAPAPCO | D28: 0 | E28: 61331.23 | F28: 51528.28 | G28: =E28-F28 -> 9802.95 | H28: =D28+G28 -> 9802.95 | I28: Accounts receivable
B29: 0400-17 | C29: STAR PLASTIC TRADING COMPANY | D29: 0 | E29: 651340.45 | F29: 486660 | G29: =E29-F29 -> 164680.45 | H29: =D29+G29 -> 164680.45 | I29: Accounts receivable
B30: 0400-20 | C30: Zomorrodah Factory Plastic Industries | D30: 0 | E30: 13878.71 | F30: 13885.93 | G30: =E30-F30 -> -7.22 | H30: =D30+G30 -> -7.22 | I30: Accounts receivable
B31: 0400-25 | C31: Various Customers | D31: 0 | E31: 0 | F31: 6880 | G31: =E31-F31 -> -6880 | H31: =D31+G31 -> -6880 | I31: Accounts receivable
B32: 0400-26 | C32: Shawahid Al-Jazeera Company Ltd | D32: 0 | E32: 24840 | F32: 24840 | G32: =E32-F32 -> 0 | H32: =D32+G32 -> 0 | I32: Accounts receivable
... B81: 0400-146 | C81: MATUWIRIN ALBLASTIC COMPANY | D81: 0 | E81: 99264.55 | F81: 96600 | G81: =E81-F81 -> 2664.55 | H81: =D81+G81 -> 2664.55 | I81: Accounts receivable
B82: 490 | C82: VAT | G82: =E82-F82 -> 0 | H82: =D82+G82 -> 0
B83: VI-001 | C83: Vat Input Account | D83: 0 | E83: 977485.76 | F83: 741334.96 | G83: =E83-F83 -> 236150.8 | H83: =D83+G83 -> 236150.8 | I83: Other current assets
B84: VO-002 | C84: Vat Output Account | D84: 0 | E84: 2893001.9 | F84: 3096628.1 | G84: =E84-F84 -> -203626.26 | H84: =D84+G84 -> -203626.26 | I84: Other current assets
B85: VOA2-003 | C85: Net Vat Refundable / Payable. | D85: -8133.72 | E85: 159260.85 | F85: 148976.09 | G85: =E85-F85 -> 10284.76 | H85: =D85+G85 -> 2151.04 | I85: Other current assets
B86: VOA1-005 | C86: Vat Receiveable | D86: 0 | E86: 235.17 | F86: 0 | G86: =E86-F86 -> 235.17 | H86: =D86+G86 -> 235.17 | I86: Other current assets
B87: VAD-006 | C87: Vat Advance Account | D87: 37956.79 | E87: 1949.29 | F87: 39510.67 | G87: =E87-F87 -> -37561.38 | H87: =D87+G87 -> 395.41 | I87: Other current assets
B88: 601 | C88: Prepaid Expenses | G88: =E88-F88 -> 0 | H88: =D88+G88 -> 0 | I88: Prepayments and other receivables
B89: 0601-01 | C89: Prepaid-Rent Factory | D89: 0 | E89: 93143.05 | F89: 62730 | G89: =E89-F89 -> 30413.05 | H89: =D89+G89 -> 30413.05 | I89: Prepayments and other receivables
B90: 0601-02 | C90: Prepaid-Medical Insurance | D90: 0 | E90: 186025.46 | F90: 77510.55 | G90: =E90-F90 -> 108514.91 | H90: =D90+G90 -> 108514.91 | I90: Prepayments and other receivables
...

Sheet bs and cf
B1: ='[1]PL-Mgmt'!B1 -> Greencity International
B2: Balance Sheet | H2: Cash Flow Report
D3: In house | E3: In house | J3: In house | K3: In house
B4: Period | D4: 45808 | E4: 46022 | H4: Period | J4: =D4 -> 45808 | K4: =E4 -> 46022
H5: OPERATING ACTIVITIES
B6: Non Current Assets | H6: Net income before zakat and income tax | J6: =D26+D27 -> 255542.42
B7: Property, plant and equipment | D7: =SUMIF(trial!$I$7:$I$359,'bs and cf'!B7,trial!$H$7:$H$360) -> 1099812.7
B8: Capital work in progress | D8: =SUMIF(trial!$I$7:$I$359,'bs and cf'!B8,trial!$H$7:$H$360) -> 0 | E8: 0 | H8: Adjustments for:
B9: Right on use of assets | D9: =SUMIF(trial!$I$7:$I$359,'bs and cf'!B9,trial!$H$7:$H$360) -> 0 | E9: 0 | H9: Depreciation and amortization | J9: 0
B10: Intangible assets | D10: =SUMIF(trial!$I$7:$I$359,'bs and cf'!B10,trial!$H$7:$H$360) -> 0 | H10: Finance charges | J10: 0
B11: Total Non Current Assets | D11: =SUM(D7:D10) -> 1099812.7 | E11: =SUM(E7:E10) -> 0 | H11: (Gain)/Loss from sale of property and equipment | J11: 0
H12: Allowance for Obsolete & slow moving inventory | J12: 0
B13: Current Assets | H13: Employees’ end of service benefits | J13: =SUM(D33-E33) -> 359740.9
B14: Inventories | D14: =SUMIF(trial!$I$7:$I$359,'bs and cf'!B14,trial!$H$7:$H$360) -> 992885.39
B15: Accounts receivable | D15: =SUMIF(trial!$I$7:$I$359,'bs and cf'!B15,trial!$H$7:$H$360) -> 1024656.5 | H15: Changes in operating assets and liabilities:
B16: Prepayments and other receivables | D16: =SUMIF(trial!$I$7:$I$359,'bs and cf'!B16,trial!$H$7:$H$360) -> 138336 | H16: Inventories | J16: =E14-D14 -> -992885.39
B17: Other current assets | D17: =SUMIF(trial!$I$7:$I$359,'bs and cf'!B17,trial!$H$7:$H$360) -> 986606.75 | H17: Trade receivables | J17: =E15-D15 -> -1024656.5
B18: Short term debt receivable from RP | D18: =SUMIF(trial!$I$7:$I$359,'bs and cf'!B18,trial!$H$7:$H$360) -> 668205.82 | H18: Prepayments and other receivables | J18: =E16-D16 -> -138336
B19: Bank balances and cash | D19: =SUMIF(trial!$I$7:$I$359,'bs and cf'!B19,trial!$H$7:$H$360) -> 53747.59 | H19: Other current assets | J19: =E17-D17 -> -986606.75
B20: Total Current Assets | D20: =SUM(D14:D19) -> 3864438.1 | E20: =SUM(E14:E19) -> 0 | H20: Trade and other payables | J20: =SUM(D41-E41) -> 3545230.8
B21: TOTAL ASSETS | D21: =D20+D11 -> 4964250.8 | E21: =E20+E11 -> 0 | H21: Other current liabilities | J21: =D42-E42 -> 668647.96
H22: Cash from operations | J22: =SUM(J6:J21) -> 1686677.4 | K22: =SUM(K6:K21) -> 0
B23: Equity | H23: Finance cost paid | J23: 0 | K23: 0
B24: Owner Contribution | D24: =-SUMIF(trial!$I$7:$I$359,'bs and cf'!B24,trial!$H$7:$H$360) -> 135088.69 | E24: 0 | H24: Zakat paid | J24: 0 | K24: 0
B25: Statutory Reserves | D25: =-SUMIF(trial!$I$7:$I$359,'bs and cf'!B25,trial!$H$7:$H$360) -> 0 | E25: 0 | H25: Employees’ end of service benefit paid | J25: 0 | K25: 0
B26: Current Year Profit (Loss) | D26: =-SUMIF(trial!$I$7:$I$359,'bs and cf'!B26,trial!$H$7:$H$360) -> 316920.94 | E26: 0 | H26: Net cash from operating activities | J26: =SUM(J22:J25) -> 1686677.4 | K26: =SUM(K22:K25) -> 0
B27: Retained Earnings | D27: =-SUMIF(trial!$I$7:$I$359,'bs and cf'!B27,trial!$H$7:$H$360) -> -61378.52
B28: Total equity | D28: =SUM(D24:D27) -> 390631.11 | E28: =SUM(E24:E27) -> 0 | H28: INVESTING ACTIVITIES
H29: Acquisition of property and equipment and intangible assets | J29: =E11-D11 -> -1099812.7
B30: Non-current liability | H30: Owner Contribution | J30: =SUM(D24-E24) -> 135088.69 | K30: 0
B31: Long-term loans | D31: =-SUMIF(trial!$I$7:$I$359,'bs and cf'!B31,trial!$H$7:$H$360) -> 0 | E31: 0 | H31: Proceeds from disposal of PPE | J31: 0 | K31: 0
B32: Long-term lease liability | D32: =-SUMIF(trial!$I$7:$I$359,'bs and cf'!B32,trial!$H$7:$H$360) -> 0 | E32: 0 | H32: Other Financial Liability | K32: 0
B33: Employees' end of service benefits | D33: =-SUMIF(trial!$I$7:$I$359,'bs and cf'!B33,trial!$H$7:$H$360) -> 359740.9 | H33: Short term loan | J33: =E18-D18 -> -668205.82
B34: Total Non Current liabilities | D34: =SUM(D31:D33) -> 359740.9 | E34: =SUM(E31:E33) -> 0 | H34: Net cash from investing activities | J34: =SUM(J29:J33) -> -1632929.9 | K34: =SUM(K29:K33) -> 0
B36: Current liabilities | H36: FINANCING ACTIVITIES
B37: Zakat Payable | D37: =-SUMIF(trial!$I$7:$I$359,'bs and cf'!B37,trial!$H$7:$H$360) -> 0 | E37: 0 | H37: Net cash in short term borrowings | J37: =D40-E40 -> 0
B38: Current portion of long-term debt | D38: =-SUMIF(trial!$I$7:$I$359,'bs and cf'!B38,trial!$H$7:$H$360) -> 0 | E38: 0 | H38: Proceeds from long term borrowings | J38: 0
B39: Current portion of lease liability | D39: =-SUMIF(trial!$I$7:$I$359,'bs and cf'!B39,trial!$H$7:$H$360) -> 0 | E39: 0 | H39: Repayments of long term borrowings | J39: 0 | K39: 0
B40: Short-term borrowings | D40: =-SUMIF(trial!$I$7:$I$359,'bs and cf'!B40,trial!$H$7:$H$360) -> 0 | H40: Principal Payments of lease liability | J40: 0 | K40: 0
B41: Trade and other payables | D41: =-SUMIF(trial!$I$7:$I$359,'bs and cf'!B41,trial!$H$7:$H$360) -> 3545230.8 | H41: Principal Payments of other financial liability | J41: 0 | K41: 0
...
